<mujocoinclude>
    <!--Mujoco Quaternion, w, x, y, z order  -->
    <body name="base">
    <inertial diaginertia="0 0 0" mass="0" pos="0 0 0" quat="0 0 0 0"/>
    <geom type="mesh" mesh="base" name="base" pos="0 0 0.33" rgba="0.5 0.5 0.5 1"></geom>
        <body name="link1">
            <inertial diaginertia="0.0233 0.0194 0.0139" mass="2.3984" pos="0.0314 0.0034 0.2529" quat="0.7071 -0.7071 0 0"></inertial>
            <joint axis="0 0 1" name="link1" range="-3.1416 3.1416" type = "hinge" armature="5" damping = "1"/>
            <!-- <joint axis="0 0 1" damping="1000" name="link1" range="-3.1416 3.1416" type = "hinge"/> -->
            <geom type="mesh" mesh="link1" name="link1" pos="0.05 0.0 0.33" quat="0.7071 -0.7071 0 0" rgba="1 1 0 1"></geom>
            <body name="link2">
                <inertial diaginertia="0.0329 0.2070 0.1884" mass="7.8019" pos="0.0298 0 0.4626" quat="0 0.7071 -0.7071 0"></inertial>
                <joint axis="0 1 0" pos="0.05 0.0 0.33" name="link2" range="-3.1416 3.1416" type = "hinge" armature="2.5" damping = "1" />
                <!-- <joint axis="0 1 0" pos="0.05 0.0 0.33" damping="1000" name="link2" range="-3.1416 3.1416" type = "hinge"/> -->
                <!-- <geom type="mesh" mesh="link2" name="link2" pos="0.05 0.0 0.77" euler="1.57 0 1.57" rgba="1 1 0 1"></geom> -->
                <geom type="mesh" mesh="link2" name="link2" pos="0.05 0.0 0.77" quat="-0.5 0.5 0.5 0.5" rgba="1 1 0 1"></geom>
                <body name="link3">
                    <inertial diaginertia="0.0081 0.0069 0.0080" mass="2.9847" pos="-0.0009 0.0207 0.7758" quat="0 0.7071 -0.7071 0"></inertial>
                    <joint axis="0 -1 0" pos="0.05 0.0 0.77" name="link3" range="-3.1416 3.1416" type = "hinge" armature="1.667" damping = "1" />
                    <!-- <joint axis="0 -1 0" pos="0.05 0.0 0.77" damping="1000" name="link3" range="-3.1416 3.1416" type = "hinge"/> -->
                    <!-- <geom type="mesh" mesh="link3" name="link3" pos="0.05 0.0 0.805" euler="1.57 -1.57 1.57" rgba="1 1 0 1"></geom> -->
                    <geom type="mesh" mesh="link3" name="link3" pos="0.05 0.0 0.805" quat = "-0.7071 0 0.7071 0" rgba="1 1 0 1"></geom>
                    <body name="link4">
                        <inertial diaginertia="0.0529 0.0057 0.0532" mass="4.1442" pos="0.2639 0.0028 0.805" quat="0.7071 0.7071 0 0"></inertial>
                        <joint axis="-1 0 0" pos="0.47 0.0 0.805" name="link4" range="-3.1416 3.1416" type = "hinge" armature="1.25" damping = "1"/>
                        <!-- <joint axis="-1 0 0" pos="0.47 0.0 0.805" damping="1000" name="link4" range="-3.1416 3.1416" type = "hinge"/> -->
                        <!-- <geom type="mesh" mesh="link4" name="link4" pos="0.47 0.0 0.805" euler="1.57 0 1.57" rgba="1 1 0 1"></geom> -->
                        <geom type="mesh" mesh="link4" name="link4" pos="0.47 0.0 0.805" quat="0.5 -0.5 0.5 0.5" rgba="1 1 0 1"></geom>
                        <body name="link5">
                            <inertial diaginertia="0.0025 0.0024 0.0012" mass="1.7004" pos="0.47 0 0.805" quat="0.7071 -0.7071 0 0"></inertial>
                            <joint axis="0 -1 0" pos="0.47 0.0 0.805" name="link5" range="-3.1416 3.1416" type = "hinge" armature="1" damping = "1"/>
                            <!-- <joint axis="0 -1 0" pos="0.47 0.0 0.805" damping="1000" name="link5" range="-3.1416 3.1416" type = "hinge"/> -->
                            <!-- <geom type="mesh" mesh="link5" name="link5" pos="0.47 0.0 0.805" euler="1.57 -1.57 1.57" rgba="1 1 0 1"></geom> -->
                            <geom type="mesh" mesh="link5" name="link5" pos="0.47 0.0 0.805" quat="-0.7071 0 0.7071 0" rgba="1 1 0 1"></geom>
                            <body name="link6">
                                <inertial diaginertia="0.00003 0.00003 0.00005" mass="1.1700" pos="0.63 0.0 0.805" quat="0 1 0 0"></inertial>
                                <!-- <inertial diaginertia="0.000132134 9.90863e-05 9.90863e-05" mass="1.1700" pos="0.55 0.0 0.805" quat="0 1 0 0"></inertial> -->
                                <joint axis="-1 0 0" pos="0.55 0.0 0.805" name="link6" range="-3.1416 3.1416" type = "hinge" armature="0.833" damping = "1"/>
                                <!-- <geom type="mesh" mesh="link6" name="link6" pos="0.55 0.0 0.805" euler="1.57 1.57 1.57" rgba="0 0 0 1"></geom> -->
                                <geom type="mesh" mesh="link6" name="link6" pos="0.55 0.0 0.805" quat="0.7071 0 0.7071 0" rgba="0 0 0 1"></geom>
                                <!-- <site name='end_effector' pos='0 0 0.02' size='0.002'/> -->
                                <body name="sensor">
                                    <!-- <geom type="mesh" mesh="sensor" name="sensor" pos="0.62 -0.0325 0.7725" euler="0 -1.57 0" rgba="0.7 0.7 0.7 1"></geom> -->
                                    <geom type="mesh" mesh="sensor" name="sensor" pos="0.62 -0.0325 0.7725" quat="-0.7071 0 0.7071 0" rgba="0.7 0.7 0.7 1"></geom>
                                    <body name="palm">
                                        <!-- <geom type="mesh" mesh="palm" name="palm" pos="0.703 -0.07 0.7875" euler="0 0 1.57" rgba="0.7 0.7 0.7 1"></geom> -->
                                        <!-- <geom type="mesh" mesh="palm" name="palm" pos="0.703 -0.07 0.7875" euler="1.57 0 0" rgba="0.7 0.7 0.7 1"></geom> -->
                                        <geom type="mesh" mesh="palm" name="palm" pos="0.703 -0.07 0.7875" quat="0.7071 0 0 0.7071" rgba="0.7 0.7 0.7 1"></geom>
                                        <body name="finger1">
                                            <!-- <geom type="mesh" mesh="finger1" name="finger1" pos="0.700 -0.027 0.7875" euler="1.57 0 0" rgba="0.7 0.7 0.7 1"></geom> -->
                                            <!-- <geom type="mesh" mesh="finger1" name="finger1" pos="0.700 -0.027 0.7875" euler="0 0 1.57" rgba="0.7 0.7 0.7 1"></geom> -->
                                            <geom type="mesh" mesh="finger1" name="finger1" pos="0.698 -0.009 0.7875" quat="0.7071 0.7071 0 0" rgba="0.7 0.7 0.7 1"></geom>
                                        </body>
                                        <!-- <body name="peg" pos="0.77 0 0.805"> -->
                                        <body name="peg" pos="0.77 0 0.805" quat="0 0.7071 0 0.7071">
                                            <geom name="peg" class="peg"/>
                                            <!-- <site name='end_effector' pos='0 0 0.02' size='0.02' quat="0 0.7071 0 0.7071"/> -->
                                            <site name='end_effector' pos='0 0 0.02' size='0.002'/>
                                        </body>
                                        <body name="finger2">
                                            <!-- <geom type="mesh" mesh="finger2" name="finger2" pos="0.700 0.027 0.7875" euler="1.57 0 0" rgba="0.7 0.7 0.7 1"></geom> -->
                                            <!-- <geom type="mesh" mesh="finger2" name="finger2" pos="0.700 0.027 0.7875" euler="0 0 1.57" rgba="0.7 0.7 0.7 1"></geom> -->
                                            <geom type="mesh" mesh="finger2" name="finger2" pos="0.698 0.015 0.7875" quat="0.7071 0.7071 0 0" rgba="0.7 0.7 0.7 1"></geom>
                                        </body>
                                    </body>
                                </body>
                            </body>
                        </body>
                    </body>
                </body>
            </body>
        </body>
    </body>    
    <!-- <body name="floor" pos="0 0 -0.02">
        <geom size="0.2 0.2 0.02" density="0" rgba="0 1 0 1" type="box"/>
    </body> -->
</mujocoinclude>